Workbook

Sheet Releases
A1: TRI Facility Name | B1: TRI Facility ID | C1: Year | D1: Chemical | E1: Releases (lb) | F1: Air Releases (lb) | G1: Water Releases (lb) | H1: Land Releases (lb) | I1: Off-Site Releases (lb)
A2: FREEPORT-MCMORAN BAGDAD INC | B2: 86321CYPRS1MAIN | C2: 2022 | D2: Dioxin and dioxin-like compounds (N150) | E2: 0.000222705 | F2: 0.000222705 | G2: 0 | H2: 0 | I2: 0
A3: FREEPORT-MCMORAN BAGDAD INC | B3: 86321CYPRS1MAIN | C3: 2023 | D3: Dioxin and dioxin-like compounds (N150) | E3: 0.0002423295 | F3: 0.0002423295 | G3: 0 | H3: 0 | I3: 0
A4: FREEPORT-MCMORAN BAGDAD INC | B4: 86321CYPRS1MAIN | C4: 2014 | D4: Molybdenum trioxide (1313-27-5) | E4: 5 | F4: 0 | G4: 0 | H4: 0 | I4: 5
A5: FREEPORT-MCMORAN MORENCI INC | B5: 85540PHLPS4521U | C5: 2014 | D5: Cobalt compounds (N096) | E5: No Releases Reported | F5: 0 | G5: 0 | H5: 0 | I5: 0
A6: FREEPORT-MCMORAN MORENCI INC | B6: 85540PHLPS4521U | C6: 2014 | D6: n-Butyl alcohol (71-36-3) | E6: No Releases Reported | F6: 0 | G6: 0 | H6: 0 | I6: 0
A7: FREEPORT-MCMORAN MORENCI INC | B7: 85540PHLPS4521U | C7: 2014 | D7: sec-Butyl alcohol (78-92-2) | E7: No Releases Reported | F7: 0 | G7: 0 | H7: 0 | I7: 0
A8: FREEPORT-MCMORAN MORENCI INC | B8: 85540PHLPS4521U | C8: 2014 | D8: Sodium nitrite (7632-00-0) | E8: No Releases Reported | F8: 0 | G8: 0 | H8: 0 | I8: 0
A9: FREEPORT-MCMORAN SAFFORD INC | B9: 85548FRPRT85NFR | C9: 2014 | D9: Cobalt compounds (N096) | E9: No Releases Reported | F9: 0 | G9: 0 | H9: 0 | I9: 0
A10: FREEPORT-MCMORAN SAFFORD INC | B10: 85548FRPRT85NFR | C10: 2014 | D10: Manganese (7439-96-5) | E10: No Releases Reported | F10: 0 | G10: 0 | H10: 0 | I10: 0
A11: FREEPORT-MCMORAN SAFFORD INC | B11: 85548FRPRT85NFR | C11: 2014 | D11: Nitrate compounds (water dissociable) (N511) | E11: No Releases Reported | F11: 0 | G11: 0 | H11: 0 | I11: 0
A12: FREEPORT-MCMORAN SIERRITA INC | B12: 85614CYPRS6200W | C12: 2014 | D12: n-Butyl alcohol (71-36-3) | E12: No Releases Reported | F12: 0 | G12: 0 | H12: 0 | I12: 0
A13: FREEPORT-MCMORAN SIERRITA INC | B13: 85614CYPRS6200W | C13: 2014 | D13: Nitrate compounds (water dissociable) (N511) | E13: No Releases Reported | F13: 0 | G13: 0 | H13: 0 | I13: 0
A14: FREEPORT-MCMORAN BAGDAD INC | B14: 86321CYPRS1MAIN | C14: 2020 | D14: Cumene (98-82-8) | E14: 250 | F14: 250 | G14: 0 | H14: 0 | I14: 0
A15: FREEPORT-MCMORAN BAGDAD INC | B15: 86321CYPRS1MAIN | C15: 2014 | D15: Ammonia (7664-41-7) | E15: 750 | F15: 750 | G15: 0 | H15: 0 | I15: 0
A16: FREEPORT-MCMORAN BAGDAD INC | B16: 86321CYPRS1MAIN | C16: 2014 | D16: Xylene (mixed isomers) (1330-20-7) | E16: 750 | F16: 750 | G16: 0 | H16: 0 | I16: 0
A17: FREEPORT-MCMORAN MORENCI INC | B17: 85540PHLPS4521U | C17: 2015 | D17: Ethylene glycol (107-21-1) | E17: No Releases Reported | F17: 0 | G17: 0 | H17: 0 | I17: 0
A18: FREEPORT-MCMORAN MORENCI INC | B18: 85540PHLPS4521U | C18: 2015 | D18: n-Butyl alcohol (71-36-3) | E18: No Releases Reported | F18: 0 | G18: 0 | H18: 0 | I18: 0
A19: FREEPORT-MCMORAN MORENCI INC | B19: 85540PHLPS4521U | C19: 2015 | D19: sec-Butyl alcohol (78-92-2) | E19: No Releases Reported | F19: 0 | G19: 0 | H19: 0 | I19: 0
A20: FREEPORT-MCMORAN MORENCI INC | B20: 85540PHLPS4521U | C20: 2015 | D20: Sodium nitrite (7632-00-0) | E20: No Releases Reported | F20: 0 | G20: 0 | H20: 0 | I20: 0
A21: FREEPORT-MCMORAN SAFFORD INC | B21: 85548FRPRT85NFR | C21: 2015 | D21: Cobalt compounds (N096) | E21: No Releases Reported | F21: 0 | G21: 0 | H21: 0 | I21: 0
A22: FREEPORT-MCMORAN SAFFORD INC | B22: 85548FRPRT85NFR | C22: 2015 | D22: Manganese (7439-96-5) | E22: No Releases Reported | F22: 0 | G22: 0 | H22: 0 | I22: 0
A23: FREEPORT-MCMORAN SAFFORD INC | B23: 85548FRPRT85NFR | C23: 2015 | D23: Nitrate compounds (water dissociable) (N511) | E23: No Releases Reported | F23: 0 | G23: 0 | H23: 0 | I23: 0
A24: FREEPORT-MCMORAN SAFFORD INC | B24: 85548FRPRT85NFR | C24: 2015 | D24: Vanadium compounds (N770) | E24: No Releases Reported | F24: 0 | G24: 0 | H24: 0 | I24: 0
A25: FREEPORT-MCMORAN SIERRITA INC | B25: 85614CYPRS6200W | C25: 2015 | D25: n-Butyl alcohol (71-36-3) | E25: No Releases Reported | F25: 0 | G25: 0 | H25: 0 | I25: 0
A26: FREEPORT-MCMORAN SIERRITA INC | B26: 85614CYPRS6200W | C26: 2015 | D26: Nitrate compounds (water dissociable) (N511) | E26: No Releases Reported | F26: 0 | G26: 0 | H26: 0 | I26: 0
A27: FREEPORT-MCMORAN BAGDAD INC | B27: 86321CYPRS1MAIN | C27: 2015 | D27: Ammonia (7664-41-7) | E27: 750 | F27: 750 | G27: 0 | H27: 0 | I27: 0
A28: FREEPORT-MCMORAN BAGDAD INC | B28: 86321CYPRS1MAIN | C28: 2015 | D28: Molybdenum trioxide (1313-27-5) | E28: 750 | F28: 0 | G28: 0 | H28: 0 | I28: 750
A29: FREEPORT-MCMORAN MORENCI INC | B29: 85540PHLPS4521U | C29: 2016 | D29: n-Butyl alcohol (71-36-3) | E29: No Releases Reported | F29: 0 | G29: 0 | H29: 0 | I29: 0
A30: FREEPORT-MCMORAN MORENCI INC | B30: 85540PHLPS4521U | C30: 2016 | D30: sec-Butyl alcohol (78-92-2) | E30: No Releases Reported | F30: 0 | G30: 0 | H30: 0 | I30: 0
A31: FREEPORT-MCMORAN MORENCI INC | B31: 85540PHLPS4521U | C31: 2016 | D31: Sodium nitrite (7632-00-0) | E31: No Releases Reported | F31: 0 | G31: 0 | H31: 0 | I31: 0
A32: FREEPORT-MCMORAN BAGDAD INC | B32: 86321CYPRS1MAIN | C32: 2016 | D32: Ammonia (7664-41-7) | E32: 750 | F32: 750 | G32: 0 | H32: 0 | I32: 0
A33: FREEPORT-MCMORAN SAFFORD INC | B33: 85548FRPRT85NFR | C33: 2016 | D33: Cobalt compounds (N096) | E33: No Releases Reported | F33: 0 | G33: 0 | H33: 0 | I33: 0
A34: FREEPORT-MCMORAN SAFFORD INC | B34: 85548FRPRT85NFR | C34: 2016 | D34: Manganese (7439-96-5) | E34: No Releases Reported | F34: 0 | G34: 0 | H34: 0 | I34: 0
A35: FREEPORT-MCMORAN SAFFORD INC | B35: 85548FRPRT85NFR | C35: 2016 | D35: Nickel (7440-02-0) | E35: No Releases Reported | F35: 0 | G35: 0 | H35: 0 | I35: 0
A36: FREEPORT-MCMORAN SAFFORD INC | B36: 85548FRPRT85NFR | C36: 2016 | D36: Nitrate compounds (water dissociable) (N511) | E36: No Releases Reported | F36: 0 | G36: 0 | H36: 0 | I36: 0
A37: FREEPORT-MCMORAN SIERRITA INC | B37: 85614CYPRS6200W | C37: 2016 | D37: n-Butyl alcohol (71-36-3) | E37: No Releases Reported | F37: 0 | G37: 0 | H37: 0 | I37: 0
A38: FREEPORT-MCMORAN SIERRITA INC | B38: 85614CYPRS6200W | C38: 2016 | D38: Nitrate compounds (water dissociable) (N511) | E38: No Releases Reported | F38: 0 | G38: 0 | H38: 0 | I38: 0
A39: FREEPORT-MCMORAN BAGDAD INC | B39: 86321CYPRS1MAIN | C39: 2016 | D39: Toluene (108-88-3) | E39: 750 | F39: 750 | G39: 0 | H39: 0 | I39: 0
A40: FREEPORT-MCMORAN BAGDAD INC | B40: 86321CYPRS1MAIN | C40: 2016 | D40: Xylene (mixed isomers) (1330-20-7) | E40: 750 | F40: 750 | G40: 0 | H40: 0 | I40: 0
...

Sheet Lead
A1: TRI Facility Name | B1: Year | C1: Chemical | D1: Releases (lb) | E1: Air Releases (lb) | F1: Water Releases (lb) | G1: Land Releases (lb) | H1: Off-Site Releases (lb)
A2: FREEPORT-MCMORAN BAGDAD INC | B2: 2021 | C2: Lead compounds (N420) | D2: 3906881.8 | E2: 242 | F2: 0.3 | G2: 3905000 | H2: 1639.5 | K2: {=_xlfn._xlws.FILTER(D2:D41, (ISNUMBER(SEARCH("SAFFORD", A2:A41))) * (B2:B41=2014))} -> 494056.3
A3: FREEPORT-MCMORAN BAGDAD INC | B3: 2022 | C3: Lead compounds (N420) | D3: 3834640.7 | E3: 391.3 | F3: 0.3 | G3: 3821000 | H3: 13249.1
A4: FREEPORT-MCMORAN BAGDAD INC | B4: 2015 | C4: Lead compounds (N420) | D4: 3651180.7 | E4: 57.7 | F4: 0 | G4: 3647000 | H4: 4123
A5: FREEPORT-MCMORAN BAGDAD INC | B5: 2023 | C5: Lead compounds (N420) | D5: 3215244 | E5: 286.7 | F5: 0 | G5: 3210000 | H5: 4957.3
A6: FREEPORT-MCMORAN BAGDAD INC | B6: 2020 | C6: Lead compounds (N420) | D6: 2562205.7 | E6: 179 | F6: 0.4 | G6: 2561000 | H6: 1026.3
A7: FREEPORT-MCMORAN BAGDAD INC | B7: 2016 | C7: Lead compounds (N420) | D7: 2410491.2 | E7: 58 | F7: 0 | G7: 2405000 | H7: 5433.2
A8: FREEPORT-MCMORAN BAGDAD INC | B8: 2017 | C8: Lead compounds (N420) | D8: 1887110.8 | E8: 49.4 | F8: 0 | G8: 1883000 | H8: 4061.4
A9: FREEPORT-MCMORAN BAGDAD INC | B9: 2019 | C9: Lead compounds (N420) | D9: 1613669.8 | E9: 167.9 | F9: 1.1 | G9: 1607000 | H9: 6500.8
A10: FREEPORT-MCMORAN BAGDAD INC | B10: 2018 | C10: Lead compounds (N420) | D10: 1136244.9 | E10: 148.5 | F10: 0.6 | G10: 1132000 | H10: 4095.8
A11: FREEPORT-MCMORAN BAGDAD INC | B11: 2014 | C11: Lead compounds (N420) | D11: 613343.9 | E11: 49 | F11: 0.9 | G11: 611200 | H11: 2094
A12: FREEPORT-MCMORAN MORENCI INC | B12: 2017 | C12: Lead compounds (N420) | D12: 7380516.3 | E12: 1223.9 | F12: 0 | G12: 7378900 | H12: 392.4
A13: FREEPORT-MCMORAN MORENCI INC | B13: 2016 | C13: Lead compounds (N420) | D13: 7316522.8 | E13: 1175.1 | F13: 0 | G13: 7314900 | H13: 447.7
A14: FREEPORT-MCMORAN MORENCI INC | B14: 2019 | C14: Lead compounds (N420) | D14: 7114863 | E14: 1862.8 | F14: 0 | G14: 7111930 | H14: 1070.2
... A41: FREEPORT-MCMORAN SIERRITA INC | B41: 2016 | C41: Lead compounds (N420) | D41: 442051.3 | E41: 41.1 | F41: 0 | G41: 442000.2 | H41: 10

Sheet Production
B1: Recoverable copper, in million lbs
B2: 2014 | C2: 2015 | D2: 2016 | E2: 2017 | F2: 2018 | G2: 2019 | H2: 2020 | I2: 2021 | J2: 2022 | K2: 2023 | L2: 2024
A3: Safford | B3: 139 | C3: 202 | D3: 230 | E3: 150 | F3: 123 | G3: 110 | H3: 161 | I3: 265 | J3: 285 | K3: 249 | L3: 245
A4: Bagdad | B4: 237 | C4: 210 | D4: 177 | E4: 173 | F4: 199 | G4: 218 | H4: 216 | I4: 184 | J4: 165 | K4: 146 | L4: 146
A5: Morenci | B5: 691 | C5: 902 | D5: 848 | E5: 737 | F5: 684 | G5: 730 | H5: 707 | I5: 631 | J5: 636 | K5: 575 | L5: 505
A6: Sierrita | B6: 195 | C6: 189 | D6: 162 | E6: 160 | F6: 152 | G6: 160 | H6: 178 | I6: 189 | J6: 194 | K6: 185 | L6: 165
B8: Recoverable copper, in metric ton
B9: 2014 | C9: 2015 | D9: 2016 | E9: 2017 | F9: 2018 | G9: 2019 | H9: 2020 | I9: 2021 | J9: 2022 | K9: 2023 | L9: 2024
A10: Safford | B10: =B3*1000000/(2204.62) -> 63049.414 | C10: =C3*1000000/(2204.62) -> 91625.768 | D10: =D3*1000000/(2204.62) -> 104326.37 | E10: =E3*1000000/(2204.62) -> 68038.936 | F10: =F3*1000000/(2204.62) -> 55791.928 | G10: =G3*1000000/(2204.62) -> 49895.22 | H10: =H3*1000000/(2204.62) -> 73028.458 | I10: =I3*1000000/(2204.62) -> 120202.12 | ... L10: =L3*1000000/(2204.62) -> 111130.26
A11: Bagdad | B11: =B4*1000000/(2204.62) -> 107501.52 | C11: =C4*1000000/(2204.62) -> 95254.511 | D11: =D4*1000000/(2204.62) -> 80285.945 | E11: =E4*1000000/(2204.62) -> 78471.573 | F11: =F4*1000000/(2204.62) -> 90264.989 | G11: =G4*1000000/(2204.62) -> 98883.254 | H11: =H4*1000000/(2204.62) -> 97976.068 | I11: =I4*1000000/(2204.62) -> 83461.095 | ... L11: =L4*1000000/(2204.62) -> 66224.565
A12: Morenci | B12: =B5*1000000/(2204.62) -> 313432.7 | C12: =C5*1000000/(2204.62) -> 409140.8 | D12: =D5*1000000/(2204.62) -> 384646.79 | E12: =E5*1000000/(2204.62) -> 334297.97 | F12: =F5*1000000/(2204.62) -> 310257.55 | G12: =G5*1000000/(2204.62) -> 331122.82 | H12: =H5*1000000/(2204.62) -> 320690.19 | I12: =I5*1000000/(2204.62) -> 286217.13 | ... L12: =L5*1000000/(2204.62) -> 229064.42
A13: Sierrita | B13: =B6*1000000/(2204.62) -> 88450.617 | C13: =C6*1000000/(2204.62) -> 85729.06 | D13: =D6*1000000/(2204.62) -> 73482.051 | E13: =E6*1000000/(2204.62) -> 72574.866 | F13: =F6*1000000/(2204.62) -> 68946.122 | G13: =G6*1000000/(2204.62) -> 72574.866 | H13: =H6*1000000/(2204.62) -> 80739.538 | I13: =I6*1000000/(2204.62) -> 85729.06 | ... L13: =L6*1000000/(2204.62) -> 74842.83

Sheet Normalized
A1: Mine | B1: 2014 | C1: 2015 | D1: 2016 | E1: 2017 | F1: 2018 | G1: 2019 | H1: 2020 | I1: 2021 | J1: 2022 | K1: 2023
A2: Safford | B2: {=_xlfn._xlws.FILTER(Lead!$D$2:$D$41, (ISNUMBER(SEARCH($A2, Lead!$A$2:$A$41))) * (Lead!$B$2:$B$41=B$1))/Production!B3} -> 3554.3619 | C2: {=_xlfn._xlws.FILTER(Lead!$D$2:$D$41, (ISNUMBER(SEARCH($A2, Lead!$A$2:$A$41))) * (Lead!$B$2:$B$41=C$1))/Production!C3} -> 1282.5787 | D2: {=_xlfn._xlws.FILTER(Lead!$D$2:$D$41, (ISNUMBER(SEARCH($A2, Lead!$A$2:$A$41))) * (Lead!$B$2:$B$41=D$1))/Production!D3} -> 1053.1922 | E2: {=_xlfn._xlws.FILTER(Lead!$D$2:$D$41, (ISNUMBER(SEARCH($A2, Lead!$A$2:$A$41))) * (Lead!$B$2:$B$41=E$1))/Production!E3} -> 1286.998 | F2: {=_xlfn._xlws.FILTER(Lead!$D$2:$D$41, (ISNUMBER(SEARCH($A2, Lead!$A$2:$A$41))) * (Lead!$B$2:$B$41=F$1))/Production!F3} -> 2139.9626 | G2: {=_xlfn._xlws.FILTER(Lead!$D$2:$D$41, (ISNUMBER(SEARCH($A2, Lead!$A$2:$A$41))) * (Lead!$B$2:$B$41=G$1))/Production!G3} -> 2592.3936 | H2: {=_xlfn._xlws.FILTER(Lead!$D$2:$D$41, (ISNUMBER(SEARCH($A2, Lead!$A$2:$A$41))) * (Lead!$B$2:$B$41=H$1))/Production!H3} -> 4869.2472 | I2: {=_xlfn._xlws.FILTER(Lead!$D$2:$D$41, (ISNUMBER(SEARCH($A2, Lead!$A$2:$A$41))) * (Lead!$B$2:$B$41=I$1))/Production!I3} -> 2728.7189 | ... K2: {=_xlfn._xlws.FILTER(Lead!$D$2:$D$41, (ISNUMBER(SEARCH($A2, Lead!$A$2:$A$41))) * (Lead!$B$2:$B$41=K$1))/Production!K3} -> 5984.8273
A3: Bagdad | B3: {=_xlfn._xlws.FILTER(Lead!$D$2:$D$41, (ISNUMBER(SEARCH($A3, Lead!$A$2:$A$41))) * (Lead!$B$2:$B$41=B$1))/Production!B4} -> 2587.9489 | C3: {=_xlfn._xlws.FILTER(Lead!$D$2:$D$41, (ISNUMBER(SEARCH($A3, Lead!$A$2:$A$41))) * (Lead!$B$2:$B$41=C$1))/Production!C4} -> 17386.575 | D3: {=_xlfn._xlws.FILTER(Lead!$D$2:$D$41, (ISNUMBER(SEARCH($A3, Lead!$A$2:$A$41))) * (Lead!$B$2:$B$41=D$1))/Production!D4} -> 13618.594 | E3: {=_xlfn._xlws.FILTER(Lead!$D$2:$D$41, (ISNUMBER(SEARCH($A3, Lead!$A$2:$A$41))) * (Lead!$B$2:$B$41=E$1))/Production!E4} -> 10908.155 | F3: {=_xlfn._xlws.FILTER(Lead!$D$2:$D$41, (ISNUMBER(SEARCH($A3, Lead!$A$2:$A$41))) * (Lead!$B$2:$B$41=F$1))/Production!F4} -> 5709.7734 | G3: {=_xlfn._xlws.FILTER(Lead!$D$2:$D$41, (ISNUMBER(SEARCH($A3, Lead!$A$2:$A$41))) * (Lead!$B$2:$B$41=G$1))/Production!G4} -> 7402.155 | H3: {=_xlfn._xlws.FILTER(Lead!$D$2:$D$41, (ISNUMBER(SEARCH($A3, Lead!$A$2:$A$41))) * (Lead!$B$2:$B$41=H$1))/Production!H4} -> 11862.063 | I3: {=_xlfn._xlws.FILTER(Lead!$D$2:$D$41, (ISNUMBER(SEARCH($A3, Lead!$A$2:$A$41))) * (Lead!$B$2:$B$41=I$1))/Production!I4} -> 21233.053 | ... K3: {=_xlfn._xlws.FILTER(Lead!$D$2:$D$41, (ISNUMBER(SEARCH($A3, Lead!$A$2:$A$41))) * (Lead!$B$2:$B$41=K$1))/Production!K4} -> 22022.219
A4: Morenci | B4: {=_xlfn._xlws.FILTER(Lead!$D$2:$D$41, (ISNUMBER(SEARCH($A4, Lead!$A$2:$A$41))) * (Lead!$B$2:$B$41=B$1))/Production!B5} -> 6372.7454 | C4: {=_xlfn._xlws.FILTER(Lead!$D$2:$D$41, (ISNUMBER(SEARCH($A4, Lead!$A$2:$A$41))) * (Lead!$B$2:$B$41=C$1))/Production!C5} -> 7387.2798 | D4: {=_xlfn._xlws.FILTER(Lead!$D$2:$D$41, (ISNUMBER(SEARCH($A4, Lead!$A$2:$A$41))) * (Lead!$B$2:$B$41=D$1))/Production!D5} -> 8627.975 | E4: {=_xlfn._xlws.FILTER(Lead!$D$2:$D$41, (ISNUMBER(SEARCH($A4, Lead!$A$2:$A$41))) * (Lead!$B$2:$B$41=E$1))/Production!E5} -> 10014.269 | F4: {=_xlfn._xlws.FILTER(Lead!$D$2:$D$41, (ISNUMBER(SEARCH($A4, Lead!$A$2:$A$41))) * (Lead!$B$2:$B$41=F$1))/Production!F5} -> 10172.118 | G4: {=_xlfn._xlws.FILTER(Lead!$D$2:$D$41, (ISNUMBER(SEARCH($A4, Lead!$A$2:$A$41))) * (Lead!$B$2:$B$41=G$1))/Production!G5} -> 9746.3877 | H4: {=_xlfn._xlws.FILTER(Lead!$D$2:$D$41, (ISNUMBER(SEARCH($A4, Lead!$A$2:$A$41))) * (Lead!$B$2:$B$41=H$1))/Production!H5} -> 8259.0001 | I4: {=_xlfn._xlws.FILTER(Lead!$D$2:$D$41, (ISNUMBER(SEARCH($A4, Lead!$A$2:$A$41))) * (Lead!$B$2:$B$41=I$1))/Production!I5} -> 8569.4702 | ... K4: {=_xlfn._xlws.FILTER(Lead!$D$2:$D$41, (ISNUMBER(SEARCH($A4, Lead!$A$2:$A$41))) * (Lead!$B$2:$B$41=K$1))/Production!K5} -> 2068.4442
A5: Sierrita | B5: {=_xlfn._xlws.FILTER(Lead!$D$2:$D$41, (ISNUMBER(SEARCH($A5, Lead!$A$2:$A$41))) * (Lead!$B$2:$B$41=B$1))/Production!B6} -> 4451.6487 | C5: {=_xlfn._xlws.FILTER(Lead!$D$2:$D$41, (ISNUMBER(SEARCH($A5, Lead!$A$2:$A$41))) * (Lead!$B$2:$B$41=C$1))/Production!C6} -> 3799.6397 | D5: {=_xlfn._xlws.FILTER(Lead!$D$2:$D$41, (ISNUMBER(SEARCH($A5, Lead!$A$2:$A$41))) * (Lead!$B$2:$B$41=D$1))/Production!D6} -> 2728.7117 | E5: {=_xlfn._xlws.FILTER(Lead!$D$2:$D$41, (ISNUMBER(SEARCH($A5, Lead!$A$2:$A$41))) * (Lead!$B$2:$B$41=E$1))/Production!E6} -> 3165.2287 | F5: {=_xlfn._xlws.FILTER(Lead!$D$2:$D$41, (ISNUMBER(SEARCH($A5, Lead!$A$2:$A$41))) * (Lead!$B$2:$B$41=F$1))/Production!F6} -> 4290.025 | G5: {=_xlfn._xlws.FILTER(Lead!$D$2:$D$41, (ISNUMBER(SEARCH($A5, Lead!$A$2:$A$41))) * (Lead!$B$2:$B$41=G$1))/Production!G6} -> 4244.3019 | H5: {=_xlfn._xlws.FILTER(Lead!$D$2:$D$41, (ISNUMBER(SEARCH($A5, Lead!$A$2:$A$41))) * (Lead!$B$2:$B$41=H$1))/Production!H6} -> 3376.832 | I5: {=_xlfn._xlws.FILTER(Lead!$D$2:$D$41, (ISNUMBER(SEARCH($A5, Lead!$A$2:$A$41))) * (Lead!$B$2:$B$41=I$1))/Production!I6} -> 5672.3254 | ... K5: {=_xlfn._xlws.FILTER(Lead!$D$2:$D$41, (ISNUMBER(SEARCH($A5, Lead!$A$2:$A$41))) * (Lead!$B$2:$B$41=K$1))/Production!K6} -> 9044.2
